Workbook

Sheet 0_개요
B1: 레일 이동하중 — 3방향(X·Y·Z) 힘 산정 공식설명
B2: 구면진자(사람) + 트롤리 모델 · 노드별 ACC/CON/DEC 동역학 산정
B4: ■ 무엇을 계산하나
B5: 모델 | C5: 레일을 따라 트롤리(동력체)가 달리고, 그 아래 줄(길이 L)에 사람이 구면진자처럼 매달린다. 각 레일 부착노드에 걸리는 전역좌표 힘 F=(Fx,Fy,Fz)를 주행 3케이스에 대해 산정한다.
B6: 3케이스 | C6: ACC=최대가속 / CON=최고정속 / DEC=비상감속. 케이스마다 트롤리 가속도가 달라 진자가 기울고, 그 결과 X·Y·Z 분담이 달라진다.
B8: ■ X·Y·Z 힘은 어떻게 갈라지나 (핵심)
B9: 한 줄 요약 | C9: 줄이 '기울어지는 것'이 X·Y의 근원이다. 직선·정속이면 줄이 연직 → 힘은 Z뿐. 트롤리가 수평으로 가속(접선/제동/원심)하면 → 느껴지는 중력 g_eff가 기울고 → 줄이 기울고 → 장력 T가 X·Y로 투영된다. 동시에 트롤리 자체 관성반작용 −m_t·a도 X·Y에 직접 더해진다.
B10: 최종식 | C10: F = −m_t·a_trolley − m_t·g·ẑ + T·n
B11: 항1 −m_t·a_trolley | C11: 트롤리 가속 반작용 → 주로 수평(X·Y)
B12: 항2 −m_t·g·ẑ | C12: 트롤리 자중 → Z
B13: 항3 T·n | C13: 줄 장력을 '기운 줄방향 n'으로 → n이 기울어 X·Y·Z 전부에 분배
B15: ■ 시트 안내
B16: 1_입력값 | C16: 제원·중력·노드 기하 입력값과 파생값(주기 등).
B17: 2_핵심공식 | C17: 구면진자 5대 공식(g_eff·운동방정식·장력·노드힘·DAF).
B18: ★3_3케이스흐름 | C18: 노드 #1004(경사+곡선) 하나로 ACC/CON/DEC 단계별 공식 흐름. 정상상태는 라이브 수식.
B19: 4_지배케이스 | C19: 케이스별 최종 F 비교·포락·지배케이스, 왜 다른가 해설.
B21: ■ 검증

Sheet 1_입력값
B1: 1. 입력값 및 파생값
B3: 항목 | C3: 기호 | D3: 값 | E3: 단위 | F3: 비고
B4: 사람(운전자) 무게 | C4: m_p | D4: 150 | E4: kg | F4: 파란값=입력
B5: 트롤리(동력체) 무게 | C5: m_t | D5: 30 | E5: kg
B6: 줄 길이 | C6: L | D6: 1.5 | E6: m | F6: 진자 길이
B7: 중력가속도 | C7: g | D7: 9.80665 | E7: m/s² | F7: GRAVITY
B8: 진자 감쇠비 | C8: ζ | D8: 0.03 | E8: - | F8: GUI 고급설정(0.02 덮어씀)
B9: 최고속도 | C9: v_max | D9: 2 | E9: m/s | F9: 원심력·정속에 사용
B10: 가속 상한 | C10: a_acc | D10: 2 | E10: m/s² | F10: 마력산정 78.7 → 상한 2.0 클램프
B11: 비상감속 | C11: a_brake | D11: 4 | E11: m/s² | F11: DEC 접선감속
B12: 사람 정적자중 | C12: W_p = m_p·g | D12: =D4*D7 -> 1470.9975 | E12: N | F12: DAF 기준하중
B13: 고유각진동수 | C13: ωₙ = √(g/L) | D13: =SQRT(D7/D6) -> 2.5569057 | E13: rad/s
B14: 진자주기 | C14: Tₙ = 2π√(L/g) | D14: =2*PI()*SQRT(D6/D7) -> 2.4573395 | E14: s | F14: 적분구간=3·Tₙ
B16: 검증 노드 #1004 — 경사(15°) 헬릭스 곡선부 (X·Y·Z 모두 발생)
B17: 항목 | C17: 기호 | D17: 값 | E17: 단위 | F17: 비고
B18: 접선벡터 x | C18: t̂x | D18: -0.69340631 | E18: - | F18: 경로 진행방향(단위벡터)
B19: 접선벡터 y | C19: t̂y | D19: 0.67232194 | E19: -
B20: 접선벡터 z | C20: t̂z | D20: 0.25917348 | E20: - | F20: 경사 → z≠0
B21: 주법선 x | C21: n̂x | D21: -0.6961046 | E21: - | F21: 곡률중심 방향(단위벡터)
B22: 주법선 y | C22: n̂y | D22: -0.71794038 | E22: -
B23: 주법선 z | C23: n̂z | D23: 1.44619e-05 | E23: - | F23: ≈0 (수평면 곡률)
B24: 곡률반경 | C24: R | D24: 3.189377 | E24: m
B25: 시작점부터 거리 | C25: s | D25: 0.86062364 | E25: m | F25: ACC 통과속도 산정용

Sheet 2_핵심공식
B1: 2. 구면진자 동역학 핵심 공식
B3: 단계 | C3: 수식 | D3: 의미
B4: ① | C4: g_eff = −g·ẑ − a_trolley | D4: 유효중력. 트롤리가 가속하면 관성력이 더해져 '느껴지는 중력'이 비스듬해진다. 줄은 g_eff 방향으로 매달린다.
B5: ② | C5: n̈ = (1/L)[g_eff−(g_eff·n)n] − (ṅ·ṅ)n − 2ζωₙ·ṅ | D5: 줄방향 n의 운동방정식(RK4 적분). 1항=복원(흔들림), 2항=줄길이 일정 구속, 3항=감쇠. 정상상태는 흔들림이 멎어 n=g_eff/|g_eff|.
B6: ③ | C6: T = m_p·[(g_eff·n) + L·(ṅ·ṅ)] | D6: 줄 장력. 정상상태(ṅ=0): T = m_p·(g_eff·n) = m_p·|g_eff|.
B7: ④ | C7: F = −m_t·a_trolley − m_t·g·ẑ + T·n | D7: ★레일 노드(부착점) 힘 — 최종 X·Y·Z★. 1항=트롤리 가속 반작용(주로 수평), 2항=트롤리 자중(Z), 3항=장력을 기운 줄방향으로(전 방향).
B8: ⑤ | C8: DAF = T_max / (m_p·g) | D8: 동적증폭계수. 과도 흔들림으로 정적자중 대비 장력이 얼마나 커지나. ACC·DEC는 >1, CON은 ≈1.

Sheet ★3_3케이스흐름
B1: 3. 세 주행케이스 공식 흐름 — 노드 #1004 (경사+곡선, X·Y·Z 모두 발생)
B2: 정상상태 체인 = 라이브 수식(시트1 참조) · RK4 과도최대값(노랑) = dynamics.py 코드 출력
B4: 공통 입력 (시트1에서 링크)
B5: m_p [kg] | C5: =1_입력값!D4 -> 150
B6: m_t [kg] | C6: =1_입력값!D5 -> 30
B7: g [m/s²] | C7: =1_입력값!D7 -> 9.80665
B8: v_max [m/s] | C8: =1_입력값!D9 -> 2
B9: a_acc [m/s²] | C9: =1_입력값!D10 -> 2
B10: a_brake [m/s²] | C10: =1_입력값!D11 -> 4
B11: t̂x | C11: =1_입력값!D18 -> -0.69340631
B12: t̂y | C12: =1_입력값!D19 -> 0.67232194
B13: t̂z | C13: =1_입력값!D20 -> 0.25917348
B14: n̂x | C14: =1_입력값!D21 -> -0.6961046
B15: n̂y | C15: =1_입력값!D22 -> -0.71794038
B16: n̂z | C16: =1_입력값!D23 -> 1.44619e-05
B17: R [m] | C17: =1_입력값!D24 -> 3.189377
B18: s [m] | C18: =1_입력값!D25 -> 0.86062364
A21: 단계 | B21: 항목 / 성분 | C21: ACC 최대가속 | D21: CON 최고정속 | E21: DEC 비상감속 | F21: 설명
A22: ① | B22: v 통과속도 [m/s] | C22: =MIN(SQRT(2*$C$9*$C$18),$C$8) -> 1.8553961 | D22: =$C$8 -> 2 | E22: =$C$8 -> 2 | F22: ACC=min(√(2·a·s),v_max), CON·DEC=v_max
B23: a_tan 접선가속 [m/s²] | C23: =IF(C22<$C$8-0.000001,$C$9,0) -> 2 | D23: =0 -> 0 | E23: =-$C$10 -> -4 | F23: ACC=+a_acc(가속구간), CON=0, DEC=−a_brake
A24: ② | B24: a_c = v²/R·n̂ (x) | C24: =C22^2/$C$17*$C$14 -> -0.75134934 | D24: =D22^2/$C$17*$C$14 -> -0.87302894 | E24: =E22^2/$C$17*$C$14 -> -0.87302894 | F24: 원심가속도. v는 ACC만 다름
B25: (y) | C25: =C22^2/$C$17*$C$15 -> -0.77491807 | D25: =D22^2/$C$17*$C$15 -> -0.90041458 | E25: =E22^2/$C$17*$C$15 -> -0.90041458
B26: (z) | C26: =C22^2/$C$17*$C$16 -> 1.5609636e-05 | D26: =D22^2/$C$17*$C$16 -> 1.8137586e-05 | E26: =E22^2/$C$17*$C$16 -> 1.8137586e-05
B27: a_tr = a_tan·t̂ + a_c (x) | C27: =C23*$C$11+C24 -> -2.138162 | D27: =D23*$C$11+D24 -> -0.87302894 | E27: =E23*$C$11+E24 -> 1.9005963 | F27: 트롤리 가속도. DEC만 접선항 큼
B28: (y) | C28: =C23*$C$12+C25 -> 0.56972581 | D28: =D23*$C$12+D25 -> -0.90041458 | E28: =E23*$C$12+E25 -> -3.5897023
B29: (z) | C29: =C23*$C$13+C26 -> 0.51836258 | D29: =D23*$C$13+D26 -> 1.8137586e-05 | E29: =E23*$C$13+E26 -> -1.0366758
A30: ③ | B30: g_eff = −g·ẑ − a_tr (x) | C30: =-C27 -> 2.138162 | D30: =-D27 -> 0.87302894 | E30: =-E27 -> -1.9005963 | F30: 느껴지는 중력 → 기울어짐
B31: (y) | C31: =-C28 -> -0.56972581 | D31: =-D28 -> 0.90041458 | E31: =-E28 -> 3.5897023
B32: (z) | C32: =-$C$7-C29 -> -10.325013 | D32: =-$C$7-D29 -> -9.8066681 | E32: =-$C$7-E29 -> -8.7699742
B33: |g_eff| [m/s²] | C33: =SQRT(C30^2+C31^2+C32^2) -> 10.559461 | D33: =SQRT(D30^2+D31^2+D32^2) -> 9.8865396 | E33: =SQRT(E30^2+E31^2+E32^2) -> 9.6649199 | F33: 크기
A34: ④ | B34: n = g_eff/|g_eff| (x) | C34: =C30/C33 -> 0.2024878 | D34: =D30/D33 -> 0.088304803 | E34: =E30/E33 -> -0.19664895 | F34: 줄 단위방향
B35: (y) | C35: =C31/C33 -> -0.053954063 | D35: =D31/D33 -> 0.091074796 | E35: =E31/E33 -> 0.37141563
B36: (z) | C36: =C32/C33 -> -0.97779735 | D36: =D32/D33 -> -0.99192119 | E36: =E32/E33 -> -0.90740268
B37: 연직기울기 θ [°] | C37: =DEGREES(ACOS(-C36)) -> 12.096143 | D37: =DEGREES(ACOS(-D36)) -> 7.28793 | E37: =DEGREES(ACOS(-E36)) -> 24.851147 | F37: 줄이 연직에서 기운 각
A38: ⑤ | B38: T_ss = m_p·|g_eff| [N] | C38: =$C$5*C33 -> 1583.9191 | D38: =$C$5*D33 -> 1482.9809 | E38: =$C$5*E33 -> 1449.738 | F38: 정상상태 장력(닫힌식)
A39: ⑥ | B39: 항1 −m_t·a_tr (x) | C39: =-$C$6*C27 -> 64.144859 | D39: =-$C$6*D27 -> 26.190868 | E39: =-$C$6*E27 -> -57.017889 | F39: 트롤리 관성반작용(수평)
B40: (y) | C40: =-$C$6*C28 -> -17.091774 | D40: =-$C$6*D28 -> 27.012437 | E40: =-$C$6*E28 -> 107.69107
B41: (z) | C41: =-$C$6*C29 -> -15.550877 | D41: =-$C$6*D29 -> -0.00054412759 | E41: =-$C$6*E29 -> 31.100274
B42: 항2 −m_t·g·ẑ (x,y) | C42: =0 -> 0 | D42: =0 -> 0 | E42: =0 -> 0 | F42: 트롤리 자중(Z만)
B43: (z) | C43: =-$C$6*$C$7 -> -294.1995 | D43: =-$C$6*$C$7 -> -294.1995 | E43: =-$C$6*$C$7 -> -294.1995
...

Sheet 4_지배케이스
B1: 4. 케이스별 최종하중 비교 · 지배케이스
B2: 노드 #1004 기준. 값은 ★3_3케이스흐름 시트의 F_코드(RK4 과도최대)를 링크.
B4: 성분 | C4: ACC 최대가속 | D4: CON 최고정속 | E4: DEC 비상감속 | F4: 단위
B5: Fx | C5: ='★3_3케이스흐름'!C53 -> 387.1542 | D5: ='★3_3케이스흐름'!D53 -> 157.1452 | E5: ='★3_3케이스흐름'!E53 -> -367.8002 | F5: N
B6: Fy | C6: ='★3_3케이스흐름'!C54 -> -103.1595 | D6: ='★3_3케이스흐름'!D54 -> 162.0746 | E6: ='★3_3케이스흐름'!E54 -> 711.5246 | F6: N
B7: Fz | C7: ='★3_3케이스흐름'!C55 -> -1923.6654 | D7: ='★3_3케이스흐름'!D55 -> -1765.2003 | E7: ='★3_3케이스흐름'!E55 -> -1788.603 | F7: N
B8: |F| 합력 | C8: ='★3_3케이스흐름'!C56 -> 1964.9475 | D8: ='★3_3케이스흐름'!D56 -> 1779.5772 | E8: ='★3_3케이스흐름'!E56 -> 1959.7563 | F8: N
B9: DAF | C9: ='★3_3케이스흐름'!C52 -> 1.120445 | D9: ='★3_3케이스흐름'!D52 -> 1.0081464 | E9: ='★3_3케이스흐름'!E52 -> 1.1351746 | F9: -
B11: Envelope 최대 |F| | C11: =MAX('★3_3케이스흐름'!C56,'★3_3케이스흐름'!D56,'★3_3케이스흐름'!E56) -> 1964.9475 | D11: N
B12: 지배 케이스 | C12: =IF(C11='★3_3케이스흐름'!C56,"ACC",IF(C11='★3_3케이스흐름'!D56,"CON","DEC")) -> ACC
B14: [ 왜 세 케이스가 다른가 ]
B15: • 원심가속 a_c 는 v·R 로 결정 — ACC만 통과속도 v가 낮아(가속 중) a_c가 작다.
B16: • 접선가속 a_tan 이 트롤리 가속도의 방향·크기를 가른다: ACC=+2(전진가속), CON=0, DEC=−4(제동).
B17: • 경사로(t̂z>0)에서는 a_tan 이 a_tr 의 Z성분도 바꾼다 → ACC는 g_eff를 더 아래로 당겨 장력·Fz를 키운다.
B18: • 초기 줄방향 n₀(적분 시작점)이 케이스마다 달라 과도 흔들림(DAF)이 갈린다: ACC는 연직에서 출발해 크게 흔들린다.
B20: [ 이 노드의 결과 ]
B21: • 이 노드(경사+곡선+가속구간)에서는 ACC가 근소하게 지배(|F|≈1965N vs DEC≈1960N).
B22: • 평지 직선/곡선부에서는 보통 DEC(−4)가 지배 — 노드 #8·#30 검산에서 확인.
B23: • 즉 지배케이스는 노드 위치(경사·곡률·가속구간 여부)에 따라 달라지며, 최종 설계는 전 노드 Envelope로 한다.
B25: [ 검증 ]
B26: • 위 정상상태 수식값은 dynamics.py 정상상태 해와 일치, RK4 과도값은 코드 출력 그대로.
B27: • loads.py 의 정역학 함수(device_force_at)는 현재 GUI 파이프라인에서 호출되지 않음(리포트·MGT는 100% 동역학 경로).
